[2024-08-05T15:47:35.225+0000] {local_task_job_runner.py:120} INFO - ::group::Pre task execution logs
[2024-08-05T15:47:35.256+0000] {taskinstance.py:2076} INFO - Dependencies all met for dep_context=non-requeueable deps ti=<TaskInstance: weather_dag.transform_load_weather_data manual__2024-08-05T15:47:15.128506+00:00 [queued]>
[2024-08-05T15:47:35.262+0000] {taskinstance.py:2076} INFO - Dependencies all met for dep_context=requeueable deps ti=<TaskInstance: weather_dag.transform_load_weather_data manual__2024-08-05T15:47:15.128506+00:00 [queued]>
[2024-08-05T15:47:35.262+0000] {taskinstance.py:2306} INFO - Starting attempt 1 of 3
[2024-08-05T15:47:35.409+0000] {taskinstance.py:2330} INFO - Executing <Task(PythonOperator): transform_load_weather_data> on 2024-08-05 15:47:15.128506+00:00
[2024-08-05T15:47:35.416+0000] {standard_task_runner.py:64} INFO - Started process 20622 to run task
[2024-08-05T15:47:35.419+0000] {standard_task_runner.py:90} INFO - Running: ['airflow', 'tasks', 'run', 'weather_dag', 'transform_load_weather_data', 'manual__2024-08-05T15:47:15.128506+00:00', '--job-id', '14', '--raw', '--subdir', 'DAGS_FOLDER/weather_dag.py', '--cfg-path', '/tmp/tmpnopga4og']
[2024-08-05T15:47:35.419+0000] {standard_task_runner.py:91} INFO - Job 14: Subtask transform_load_weather_data
[2024-08-05T15:47:35.459+0000] {task_command.py:426} INFO - Running <TaskInstance: weather_dag.transform_load_weather_data manual__2024-08-05T15:47:15.128506+00:00 [running]> on host ip-172-31-17-139.us-east-2.compute.internal
[2024-08-05T15:47:35.517+0000] {taskinstance.py:2648} INFO - Exporting env vars: AIRFLOW_CTX_DAG_EMAIL='myemail@domain.com' AIRFLOW_CTX_DAG_OWNER='airflow' AIRFLOW_CTX_DAG_ID='weather_dag' AIRFLOW_CTX_TASK_ID='transform_load_weather_data' AIRFLOW_CTX_EXECUTION_DATE='2024-08-05T15:47:15.128506+00:00' AIRFLOW_CTX_TRY_NUMBER='1' AIRFLOW_CTX_DAG_RUN_ID='manual__2024-08-05T15:47:15.128506+00:00'
[2024-08-05T15:47:35.518+0000] {taskinstance.py:430} INFO - ::endgroup::
[2024-08-05T15:47:35.530+0000] {base.py:84} INFO - Using connection ID 'aws_default' for task execution.
[2024-08-05T15:47:35.555+0000] {credentials.py:1075} INFO - Found credentials from IAM Role: airflow-etl-yml
[2024-08-05T15:47:35.786+0000] {taskinstance.py:441} INFO - ::group::Post task execution logs
[2024-08-05T15:47:35.786+0000] {taskinstance.py:2905} ERROR - Task failed with exception
Traceback (most recent call last):
  File "/home/ubuntu/airflow_venv/lib/python3.12/site-packages/boto3/s3/transfer.py", line 372, in upload_file
    future.result()
  File "/home/ubuntu/airflow_venv/lib/python3.12/site-packages/s3transfer/futures.py", line 103, in result
    return self._coordinator.result()
           ^^^^^^^^^^^^^^^^^^^^^^^^^^
  File "/home/ubuntu/airflow_venv/lib/python3.12/site-packages/s3transfer/futures.py", line 266, in result
    raise self._exception
  File "/home/ubuntu/airflow_venv/lib/python3.12/site-packages/s3transfer/tasks.py", line 139, in __call__
    return self._execute_main(kwargs)
           ^^^^^^^^^^^^^^^^^^^^^^^^^^
  File "/home/ubuntu/airflow_venv/lib/python3.12/site-packages/s3transfer/tasks.py", line 162, in _execute_main
    return_value = self._main(**kwargs)
                   ^^^^^^^^^^^^^^^^^^^^
  File "/home/ubuntu/airflow_venv/lib/python3.12/site-packages/s3transfer/upload.py", line 764, in _main
    client.put_object(Bucket=bucket, Key=key, Body=body, **extra_args)
  File "/home/ubuntu/airflow_venv/lib/python3.12/site-packages/botocore/client.py", line 565, in _api_call
    return self._make_api_call(operation_name, kwargs)
           ^^^^^^^^^^^^^^^^^^^^^^^^^^^^^^^^^^^^^^^^^^^
  File "/home/ubuntu/airflow_venv/lib/python3.12/site-packages/botocore/client.py", line 1017, in _make_api_call
    raise error_class(parsed_response, operation_name)
botocore.exceptions.ClientError: An error occurred (AccessDenied) when calling the PutObject operation: Access Denied

During handling of the above exception, another exception occurred:

Traceback (most recent call last):
  File "/home/ubuntu/airflow_venv/lib/python3.12/site-packages/airflow/models/taskinstance.py", line 465, in _execute_task
    result = _execute_callable(context=context, **execute_callable_kwargs)
             ^^^^^^^^^^^^^^^^^^^^^^^^^^^^^^^^^^^^^^^^^^^^^^^^^^^^^^^^^^^^^
  File "/home/ubuntu/airflow_venv/lib/python3.12/site-packages/airflow/models/taskinstance.py", line 432, in _execute_callable
    return execute_callable(context=context, **execute_callable_kwargs)
           ^^^^^^^^^^^^^^^^^^^^^^^^^^^^^^^^^^^^^^^^^^^^^^^^^^^^^^^^^^^^
  File "/home/ubuntu/airflow_venv/lib/python3.12/site-packages/airflow/models/baseoperator.py", line 401, in wrapper
    return func(self, *args, **kwargs)
           ^^^^^^^^^^^^^^^^^^^^^^^^^^^
  File "/home/ubuntu/airflow_venv/lib/python3.12/site-packages/airflow/operators/python.py", line 235, in execute
    return_value = self.execute_callable()
                   ^^^^^^^^^^^^^^^^^^^^^^^
  File "/home/ubuntu/airflow_venv/lib/python3.12/site-packages/airflow/operators/python.py", line 252, in execute_callable
    return self.python_callable(*self.op_args, **self.op_kwargs)
           ^^^^^^^^^^^^^^^^^^^^^^^^^^^^^^^^^^^^^^^^^^^^^^^^^^^^^
  File "/home/ubuntu/airflow/dags/weather_dag.py", line 68, in transform_load_data
    s3_client.upload_file(local_file_path, 'weatherairflow-yml', file_name)
  File "/home/ubuntu/airflow_venv/lib/python3.12/site-packages/boto3/s3/inject.py", line 145, in upload_file
    return transfer.upload_file(
           ^^^^^^^^^^^^^^^^^^^^^
  File "/home/ubuntu/airflow_venv/lib/python3.12/site-packages/boto3/s3/transfer.py", line 378, in upload_file
    raise S3UploadFailedError(
boto3.exceptions.S3UploadFailedError: Failed to upload /tmp/current_weather_data_portland_05082024154735.csv to weatherairflow-yml/current_weather_data_portland_05082024154735.csv: An error occurred (AccessDenied) when calling the PutObject operation: Access Denied
[2024-08-05T15:47:35.793+0000] {taskinstance.py:1206} INFO - Marking task as UP_FOR_RETRY. dag_id=weather_dag, task_id=transform_load_weather_data, run_id=manual__2024-08-05T15:47:15.128506+00:00, execution_date=20240805T154715, start_date=20240805T154735, end_date=20240805T154735
[2024-08-05T15:47:35.806+0000] {standard_task_runner.py:110} ERROR - Failed to execute job 14 for task transform_load_weather_data (Failed to upload /tmp/current_weather_data_portland_05082024154735.csv to weatherairflow-yml/current_weather_data_portland_05082024154735.csv: An error occurred (AccessDenied) when calling the PutObject operation: Access Denied; 20622)
[2024-08-05T15:47:35.832+0000] {local_task_job_runner.py:243} INFO - Task exited with return code 1
[2024-08-05T15:47:35.844+0000] {taskinstance.py:3503} INFO - 0 downstream tasks scheduled from follow-on schedule check
[2024-08-05T15:47:35.845+0000] {local_task_job_runner.py:222} INFO - ::endgroup::
